Workbook

Sheet Suivi traitement
A1: SUIVI DE TRAITEMENT
A3: Pilotage des traitements · filtres indépendants par activité, produit et site
A5: TRAITEMENTS | E5: DOSSIERS UNIQUES | I5: COLLABORATEURS ACTIFS | M5: AGENTS NON RÉFÉRENCÉS
A6: =SUM(tblDataBrut[Nombre de dossiers traités]) -> 7 | E6: =ROWS(_xlfn.UNIQUE(tblDataBrut[Dossier])) -> #NAME? | I6: =ROWS(_xlfn.UNIQUE(tblDataBrut[Collaborateur])) -> #NAME? | M6: =COUNTIF(tblDataBrut[Collaborateur],"Agent non référencé") -> 0
A10: STATISTIQUES PAR ACTIVITÉ
A11: Mois | C11: Semaine | E11: Site
A12: Tous | C12: Tous | E12: Tous
A14: Activité | B14: Dossiers traités
A15: =IF(Paramètres!N3="","",Paramètres!N3) -> #NAME? | B15: =IF(A15="","",SUMIFS(tblDataBrut[Nombre de dossiers traités],tblDataBrut[Activité],A15,tblDataBrut[Mois],IF($A$12="Tous","*",$A$12),tblDataBrut[Semaine],IF($C$12="Tous","*",$C$12),tblDataBrut[Site],IF($E$12="Tous","*",$E$12))) -> #NAME?
A16: =IF(Paramètres!N4="","",Paramètres!N4) -> #NAME? | B16: =IF(A16="","",SUMIFS(tblDataBrut[Nombre de dossiers traités],tblDataBrut[Activité],A16,tblDataBrut[Mois],IF($A$12="Tous","*",$A$12),tblDataBrut[Semaine],IF($C$12="Tous","*",$C$12),tblDataBrut[Site],IF($E$12="Tous","*",$E$12))) -> #NAME?
A17: =IF(Paramètres!N5="","",Paramètres!N5) | B17: =IF(A17="","",SUMIFS(tblDataBrut[Nombre de dossiers traités],tblDataBrut[Activité],A17,tblDataBrut[Mois],IF($A$12="Tous","*",$A$12),tblDataBrut[Semaine],IF($C$12="Tous","*",$C$12),tblDataBrut[Site],IF($E$12="Tous","*",$E$12)))
A18: =IF(Paramètres!N6="","",Paramètres!N6) | B18: =IF(A18="","",SUMIFS(tblDataBrut[Nombre de dossiers traités],tblDataBrut[Activité],A18,tblDataBrut[Mois],IF($A$12="Tous","*",$A$12),tblDataBrut[Semaine],IF($C$12="Tous","*",$C$12),tblDataBrut[Site],IF($E$12="Tous","*",$E$12)))
A19: =IF(Paramètres!N7="","",Paramètres!N7) | B19: =IF(A19="","",SUMIFS(tblDataBrut[Nombre de dossiers traités],tblDataBrut[Activité],A19,tblDataBrut[Mois],IF($A$12="Tous","*",$A$12),tblDataBrut[Semaine],IF($C$12="Tous","*",$C$12),tblDataBrut[Site],IF($E$12="Tous","*",$E$12)))
A20: =IF(Paramètres!N8="","",Paramètres!N8) | B20: =IF(A20="","",SUMIFS(tblDataBrut[Nombre de dossiers traités],tblDataBrut[Activité],A20,tblDataBrut[Mois],IF($A$12="Tous","*",$A$12),tblDataBrut[Semaine],IF($C$12="Tous","*",$C$12),tblDataBrut[Site],IF($E$12="Tous","*",$E$12)))
A21: =IF(Paramètres!N9="","",Paramètres!N9) | B21: =IF(A21="","",SUMIFS(tblDataBrut[Nombre de dossiers traités],tblDataBrut[Activité],A21,tblDataBrut[Mois],IF($A$12="Tous","*",$A$12),tblDataBrut[Semaine],IF($C$12="Tous","*",$C$12),tblDataBrut[Site],IF($E$12="Tous","*",$E$12)))
A22: =IF(Paramètres!N10="","",Paramètres!N10) | B22: =IF(A22="","",SUMIFS(tblDataBrut[Nombre de dossiers traités],tblDataBrut[Activité],A22,tblDataBrut[Mois],IF($A$12="Tous","*",$A$12),tblDataBrut[Semaine],IF($C$12="Tous","*",$C$12),tblDataBrut[Site],IF($E$12="Tous","*",$E$12)))
A23: =IF(Paramètres!N11="","",Paramètres!N11) | B23: =IF(A23="","",SUMIFS(tblDataBrut[Nombre de dossiers traités],tblDataBrut[Activité],A23,tblDataBrut[Mois],IF($A$12="Tous","*",$A$12),tblDataBrut[Semaine],IF($C$12="Tous","*",$C$12),tblDataBrut[Site],IF($E$12="Tous","*",$E$12)))
A24: =IF(Paramètres!N12="","",Paramètres!N12) | B24: =IF(A24="","",SUMIFS(tblDataBrut[Nombre de dossiers traités],tblDataBrut[Activité],A24,tblDataBrut[Mois],IF($A$12="Tous","*",$A$12),tblDataBrut[Semaine],IF($C$12="Tous","*",$C$12),tblDataBrut[Site],IF($E$12="Tous","*",$E$12)))
A25: =IF(Paramètres!N13="","",Paramètres!N13) | B25: =IF(A25="","",SUMIFS(tblDataBrut[Nombre de dossiers traités],tblDataBrut[Activité],A25,tblDataBrut[Mois],IF($A$12="Tous","*",$A$12),tblDataBrut[Semaine],IF($C$12="Tous","*",$C$12),tblDataBrut[Site],IF($E$12="Tous","*",$E$12)))
A29: STATISTIQUES PAR PRODUIT
A30: Activité | C30: Mois | E30: Semaine | G30: Date | I30: Site | K30: Dispo
A31: Tous | C31: Tous | E31: Tous | G31: Toutes | I31: Tous | K31: Tous
A33: Produit | B33: Dossiers traités
A34: =IF(Paramètres!P3="","",Paramètres!P3) -> #NAME? | B34: =IF(A34="","",IF($G$31="Toutes",SUMIFS(tblDataBrut[Nombre de dossiers traités],tblDataBrut[Produit],A34,tblDataBrut[Activité],IF($A$31="Tous","*",$A$31),tblDataBrut[Mois],IF($C$31="Tous","*",$C$31),tblDataBrut[Semaine],IF($E$31="Tous","*",$E$31),tblDataBrut[Site],IF($I$31="Tous","*",$I$31),tblDataBrut[Dispo],IF($K$31="Tous","*",$K$31)),SUMIFS(tblDataBrut[Nombre de dossiers traités],tblDataBrut[Produit],A34,tblDataBrut[Activité],IF($A$31="Tous","*",$A$31),tblDataBrut[Mois],IF($C$31="Tous","*",$C$31),tblDataBrut[Semaine],IF($E$31="Tous","*",$E$31),tblDataBrut[Site],IF($I$31="Tous","*",$I$31),tblDataBrut[Dispo],IF($K$31="Tous","*",$K$31),tblDataBrut[Date],$G$31))) -> #NAME?
A35: =IF(Paramètres!P4="","",Paramètres!P4) -> #NAME? | B35: =IF(A35="","",IF($G$31="Toutes",SUMIFS(tblDataBrut[Nombre de dossiers traités],tblDataBrut[Produit],A35,tblDataBrut[Activité],IF($A$31="Tous","*",$A$31),tblDataBrut[Mois],IF($C$31="Tous","*",$C$31),tblDataBrut[Semaine],IF($E$31="Tous","*",$E$31),tblDataBrut[Site],IF($I$31="Tous","*",$I$31),tblDataBrut[Dispo],IF($K$31="Tous","*",$K$31)),SUMIFS(tblDataBrut[Nombre de dossiers traités],tblDataBrut[Produit],A35,tblDataBrut[Activité],IF($A$31="Tous","*",$A$31),tblDataBrut[Mois],IF($C$31="Tous","*",$C$31),tblDataBrut[Semaine],IF($E$31="Tous","*",$E$31),tblDataBrut[Site],IF($I$31="Tous","*",$I$31),tblDataBrut[Dispo],IF($K$31="Tous","*",$K$31),tblDataBrut[Date],$G$31))) -> #NAME?
A36: =IF(Paramètres!P5="","",Paramètres!P5) -> #NAME? | B36: =IF(A36="","",IF($G$31="Toutes",SUMIFS(tblDataBrut[Nombre de dossiers traités],tblDataBrut[Produit],A36,tblDataBrut[Activité],IF($A$31="Tous","*",$A$31),tblDataBrut[Mois],IF($C$31="Tous","*",$C$31),tblDataBrut[Semaine],IF($E$31="Tous","*",$E$31),tblDataBrut[Site],IF($I$31="Tous","*",$I$31),tblDataBrut[Dispo],IF($K$31="Tous","*",$K$31)),SUMIFS(tblDataBrut[Nombre de dossiers traités],tblDataBrut[Produit],A36,tblDataBrut[Activité],IF($A$31="Tous","*",$A$31),tblDataBrut[Mois],IF($C$31="Tous","*",$C$31),tblDataBrut[Semaine],IF($E$31="Tous","*",$E$31),tblDataBrut[Site],IF($I$31="Tous","*",$I$31),tblDataBrut[Dispo],IF($K$31="Tous","*",$K$31),tblDataBrut[Date],$G$31))) -> #NAME?
A37: =IF(Paramètres!P6="","",Paramètres!P6) | B37: =IF(A37="","",IF($G$31="Toutes",SUMIFS(tblDataBrut[Nombre de dossiers traités],tblDataBrut[Produit],A37,tblDataBrut[Activité],IF($A$31="Tous","*",$A$31),tblDataBrut[Mois],IF($C$31="Tous","*",$C$31),tblDataBrut[Semaine],IF($E$31="Tous","*",$E$31),tblDataBrut[Site],IF($I$31="Tous","*",$I$31),tblDataBrut[Dispo],IF($K$31="Tous","*",$K$31)),SUMIFS(tblDataBrut[Nombre de dossiers traités],tblDataBrut[Produit],A37,tblDataBrut[Activité],IF($A$31="Tous","*",$A$31),tblDataBrut[Mois],IF($C$31="Tous","*",$C$31),tblDataBrut[Semaine],IF($E$31="Tous","*",$E$31),tblDataBrut[Site],IF($I$31="Tous","*",$I$31),tblDataBrut[Dispo],IF($K$31="Tous","*",$K$31),tblDataBrut[Date],$G$31)))
A38: =IF(Paramètres!P7="","",Paramètres!P7) | B38: =IF(A38="","",IF($G$31="Toutes",SUMIFS(tblDataBrut[Nombre de dossiers traités],tblDataBrut[Produit],A38,tblDataBrut[Activité],IF($A$31="Tous","*",$A$31),tblDataBrut[Mois],IF($C$31="Tous","*",$C$31),tblDataBrut[Semaine],IF($E$31="Tous","*",$E$31),tblDataBrut[Site],IF($I$31="Tous","*",$I$31),tblDataBrut[Dispo],IF($K$31="Tous","*",$K$31)),SUMIFS(tblDataBrut[Nombre de dossiers traités],tblDataBrut[Produit],A38,tblDataBrut[Activité],IF($A$31="Tous","*",$A$31),tblDataBrut[Mois],IF($C$31="Tous","*",$C$31),tblDataBrut[Semaine],IF($E$31="Tous","*",$E$31),tblDataBrut[Site],IF($I$31="Tous","*",$I$31),tblDataBrut[Dispo],IF($K$31="Tous","*",$K$31),tblDataBrut[Date],$G$31)))
A39: =IF(Paramètres!P8="","",Paramètres!P8) | B39: =IF(A39="","",IF($G$31="Toutes",SUMIFS(tblDataBrut[Nombre de dossiers traités],tblDataBrut[Produit],A39,tblDataBrut[Activité],IF($A$31="Tous","*",$A$31),tblDataBrut[Mois],IF($C$31="Tous","*",$C$31),tblDataBrut[Semaine],IF($E$31="Tous","*",$E$31),tblDataBrut[Site],IF($I$31="Tous","*",$I$31),tblDataBrut[Dispo],IF($K$31="Tous","*",$K$31)),SUMIFS(tblDataBrut[Nombre de dossiers traités],tblDataBrut[Produit],A39,tblDataBrut[Activité],IF($A$31="Tous","*",$A$31),tblDataBrut[Mois],IF($C$31="Tous","*",$C$31),tblDataBrut[Semaine],IF($E$31="Tous","*",$E$31),tblDataBrut[Site],IF($I$31="Tous","*",$I$31),tblDataBrut[Dispo],IF($K$31="Tous","*",$K$31),tblDataBrut[Date],$G$31)))
A40: =IF(Paramètres!P9="","",Paramètres!P9) | B40: =IF(A40="","",IF($G$31="Toutes",SUMIFS(tblDataBrut[Nombre de dossiers traités],tblDataBrut[Produit],A40,tblDataBrut[Activité],IF($A$31="Tous","*",$A$31),tblDataBrut[Mois],IF($C$31="Tous","*",$C$31),tblDataBrut[Semaine],IF($E$31="Tous","*",$E$31),tblDataBrut[Site],IF($I$31="Tous","*",$I$31),tblDataBrut[Dispo],IF($K$31="Tous","*",$K$31)),SUMIFS(tblDataBrut[Nombre de dossiers traités],tblDataBrut[Produit],A40,tblDataBrut[Activité],IF($A$31="Tous","*",$A$31),tblDataBrut[Mois],IF($C$31="Tous","*",$C$31),tblDataBrut[Semaine],IF($E$31="Tous","*",$E$31),tblDataBrut[Site],IF($I$31="Tous","*",$I$31),tblDataBrut[Dispo],IF($K$31="Tous","*",$K$31),tblDataBrut[Date],$G$31)))
A41: =IF(Paramètres!P10="","",Paramètres!P10) | B41: =IF(A41="","",IF($G$31="Toutes",SUMIFS(tblDataBrut[Nombre de dossiers traités],tblDataBrut[Produit],A41,tblDataBrut[Activité],IF($A$31="Tous","*",$A$31),tblDataBrut[Mois],IF($C$31="Tous","*",$C$31),tblDataBrut[Semaine],IF($E$31="Tous","*",$E$31),tblDataBrut[Site],IF($I$31="Tous","*",$I$31),tblDataBrut[Dispo],IF($K$31="Tous","*",$K$31)),SUMIFS(tblDataBrut[Nombre de dossiers traités],tblDataBrut[Produit],A41,tblDataBrut[Activité],IF($A$31="Tous","*",$A$31),tblDataBrut[Mois],IF($C$31="Tous","*",$C$31),tblDataBrut[Semaine],IF($E$31="Tous","*",$E$31),tblDataBrut[Site],IF($I$31="Tous","*",$I$31),tblDataBrut[Dispo],IF($K$31="Tous","*",$K$31),tblDataBrut[Date],$G$31)))
A42: =IF(Paramètres!P11="","",Paramètres!P11) | B42: =IF(A42="","",IF($G$31="Toutes",SUMIFS(tblDataBrut[Nombre de dossiers traités],tblDataBrut[Produit],A42,tblDataBrut[Activité],IF($A$31="Tous","*",$A$31),tblDataBrut[Mois],IF($C$31="Tous","*",$C$31),tblDataBrut[Semaine],IF($E$31="Tous","*",$E$31),tblDataBrut[Site],IF($I$31="Tous","*",$I$31),tblDataBrut[Dispo],IF($K$31="Tous","*",$K$31)),SUMIFS(tblDataBrut[Nombre de dossiers traités],tblDataBrut[Produit],A42,tblDataBrut[Activité],IF($A$31="Tous","*",$A$31),tblDataBrut[Mois],IF($C$31="Tous","*",$C$31),tblDataBrut[Semaine],IF($E$31="Tous","*",$E$31),tblDataBrut[Site],IF($I$31="Tous","*",$I$31),tblDataBrut[Dispo],IF($K$31="Tous","*",$K$31),tblDataBrut[Date],$G$31)))
A43: =IF(Paramètres!P12="","",Paramètres!P12) | B43: =IF(A43="","",IF($G$31="Toutes",SUMIFS(tblDataBrut[Nombre de dossiers traités],tblDataBrut[Produit],A43,tblDataBrut[Activité],IF($A$31="Tous","*",$A$31),tblDataBrut[Mois],IF($C$31="Tous","*",$C$31),tblDataBrut[Semaine],IF($E$31="Tous","*",$E$31),tblDataBrut[Site],IF($I$31="Tous","*",$I$31),tblDataBrut[Dispo],IF($K$31="Tous","*",$K$31)),SUMIFS(tblDataBrut[Nombre de dossiers traités],tblDataBrut[Produit],A43,tblDataBrut[Activité],IF($A$31="Tous","*",$A$31),tblDataBrut[Mois],IF($C$31="Tous","*",$C$31),tblDataBrut[Semaine],IF($E$31="Tous","*",$E$31),tblDataBrut[Site],IF($I$31="Tous","*",$I$31),tblDataBrut[Dispo],IF($K$31="Tous","*",$K$31),tblDataBrut[Date],$G$31)))
A44: =IF(Paramètres!P13="","",Paramètres!P13) | B44: =IF(A44="","",IF($G$31="Toutes",SUMIFS(tblDataBrut[Nombre de dossiers traités],tblDataBrut[Produit],A44,tblDataBrut[Activité],IF($A$31="Tous","*",$A$31),tblDataBrut[Mois],IF($C$31="Tous","*",$C$31),tblDataBrut[Semaine],IF($E$31="Tous","*",$E$31),tblDataBrut[Site],IF($I$31="Tous","*",$I$31),tblDataBrut[Dispo],IF($K$31="Tous","*",$K$31)),SUMIFS(tblDataBrut[Nombre de dossiers traités],tblDataBrut[Produit],A44,tblDataBrut[Activité],IF($A$31="Tous","*",$A$31),tblDataBrut[Mois],IF($C$31="Tous","*",$C$31),tblDataBrut[Semaine],IF($E$31="Tous","*",$E$31),tblDataBrut[Site],IF($I$31="Tous","*",$I$31),tblDataBrut[Dispo],IF($K$31="Tous","*",$K$31),tblDataBrut[Date],$G$31)))
A45: =IF(Paramètres!P14="","",Paramètres!P14) | B45: =IF(A45="","",IF($G$31="Toutes",SUMIFS(tblDataBrut[Nombre de dossiers traités],tblDataBrut[Produit],A45,tblDataBrut[Activité],IF($A$31="Tous","*",$A$31),tblDataBrut[Mois],IF($C$31="Tous","*",$C$31),tblDataBrut[Semaine],IF($E$31="Tous","*",$E$31),tblDataBrut[Site],IF($I$31="Tous","*",$I$31),tblDataBrut[Dispo],IF($K$31="Tous","*",$K$31)),SUMIFS(tblDataBrut[Nombre de dossiers traités],tblDataBrut[Produit],A45,tblDataBrut[Activité],IF($A$31="Tous","*",$A$31),tblDataBrut[Mois],IF($C$31="Tous","*",$C$31),tblDataBrut[Semaine],IF($E$31="Tous","*",$E$31),tblDataBrut[Site],IF($I$31="Tous","*",$I$31),tblDataBrut[Dispo],IF($K$31="Tous","*",$K$31),tblDataBrut[Date],$G$31)))
A48: STATISTIQUES PAR SITE
A49: Activité | C49: Mois | E49: Semaine | G49: Date | I49: Produit
A50: Tous | C50: Tous | E50: Tous | G50: Toutes | I50: Tous
A52: Site | B52: Dossiers traités
A53: =IF(Paramètres!L3="","",Paramètres!L3) -> #NAME? | B53: =IF(A53="","",IF($G$50="Toutes",SUMIFS(tblDataBrut[Nombre de dossiers traités],tblDataBrut[Site],A53,tblDataBrut[Activité],IF($A$50="Tous","*",$A$50),tblDataBrut[Mois],IF($C$50="Tous","*",$C$50),tblDataBrut[Semaine],IF($E$50="Tous","*",$E$50),tblDataBrut[Produit],IF($I$50="Tous","*",$I$50)),SUMIFS(tblDataBrut[Nombre de dossiers traités],tblDataBrut[Site],A53,tblDataBrut[Activité],IF($A$50="Tous","*",$A$50),tblDataBrut[Mois],IF($C$50="Tous","*",$C$50),tblDataBrut[Semaine],IF($E$50="Tous","*",$E$50),tblDataBrut[Produit],IF($I$50="Tous","*",$I$50),tblDataBrut[Date],$G$50))) -> #NAME?
...

Sheet Statistique
A1: STATISTIQUE · SYNTHÈSE
A3: Détail agrégé par mois, semaine, site, date, activité, produit et disponibilité
A6: Mois | B6: Semaine | C6: Site | D6: Date | E6: Activité | F6: Produit | G6: Dispo | H6: Nombre de dossiers traités
A7: 2026-08 | B7: 2026-S34 | C7: Tunis | D7: 46252 | E7: Live Console | F7: CCL SFR | G7: (Non renseigné) | H7: =SUMIFS(tblDataBrut[Nombre de dossiers traités],tblDataBrut[Mois],A7,tblDataBrut[Semaine],B7,tblDataBrut[Site],C7,tblDataBrut[Date],D7,tblDataBrut[Activité],E7,tblDataBrut[Produit],F7,tblDataBrut[Dispo],G7) -> 2
A8: 2026-08 | B8: 2026-S34 | C8: Tunis | D8: 46252 | E8: Octroi Classique | F8: CLA | G8: OUI | H8: =SUMIFS(tblDataBrut[Nombre de dossiers traités],tblDataBrut[Mois],A8,tblDataBrut[Semaine],B8,tblDataBrut[Site],C8,tblDataBrut[Date],D8,tblDataBrut[Activité],E8,tblDataBrut[Produit],F8,tblDataBrut[Dispo],G8) -> 3
A9: 2026-08 | B9: 2026-S34 | C9: Tunis | D9: 46252 | E9: Octroi Classique | F9: Lydia/BANKIN | G9: OUI | H9: =SUMIFS(tblDataBrut[Nombre de dossiers traités],tblDataBrut[Mois],A9,tblDataBrut[Semaine],B9,tblDataBrut[Site],C9,tblDataBrut[Date],D9,tblDataBrut[Activité],E9,tblDataBrut[Produit],F9,tblDataBrut[Dispo],G9) -> 1
A10: 2026-08 | B10: 2026-S34 | C10: Tunis | D10: 46253 | E10: Octroi Classique | F10: CLA | G10: OUI | H10: =SUMIFS(tblDataBrut[Nombre de dossiers traités],tblDataBrut[Mois],A10,tblDataBrut[Semaine],B10,tblDataBrut[Site],C10,tblDataBrut[Date],D10,tblDataBrut[Activité],E10,tblDataBrut[Produit],F10,tblDataBrut[Dispo],G10) -> 1

Sheet Stat par agent
A1: STATISTIQUES PAR AGENT
A3: Détail agrégé par collaborateur avec filtres Excel sur toutes les dimensions
A6: Mois | B6: Semaine | C6: Site | D6: Collaborateur | E6: Date | F6: Activité | G6: Produit | H6: Dispo | I6: Nombre de dossiers traités
A7: 2026-08 | B7: 2026-S34 | C7: Tunis | D7: chaachoui youssef | E7: 46252 | F7: Live Console | G7: CCL SFR | H7: (Non renseigné) | I7: =SUMIFS(tblDataBrut[Nombre de dossiers traités],tblDataBrut[Mois],A7,tblDataBrut[Semaine],B7,tblDataBrut[Site],C7,tblDataBrut[Collaborateur],D7,tblDataBrut[Date],E7,tblDataBrut[Activité],F7,tblDataBrut[Produit],G7,tblDataBrut[Dispo],H7) -> 2
A8: 2026-08 | B8: 2026-S34 | C8: Tunis | D8: chaachoui youssef | E8: 46252 | F8: Octroi Classique | G8: CLA | H8: OUI | I8: =SUMIFS(tblDataBrut[Nombre de dossiers traités],tblDataBrut[Mois],A8,tblDataBrut[Semaine],B8,tblDataBrut[Site],C8,tblDataBrut[Collaborateur],D8,tblDataBrut[Date],E8,tblDataBrut[Activité],F8,tblDataBrut[Produit],G8,tblDataBrut[Dispo],H8) -> 3
A9: 2026-08 | B9: 2026-S34 | C9: Tunis | D9: chaachoui youssef | E9: 46252 | F9: Octroi Classique | G9: Lydia/BANKIN | H9: OUI | I9: =SUMIFS(tblDataBrut[Nombre de dossiers traités],tblDataBrut[Mois],A9,tblDataBrut[Semaine],B9,tblDataBrut[Site],C9,tblDataBrut[Collaborateur],D9,tblDataBrut[Date],E9,tblDataBrut[Activité],F9,tblDataBrut[Produit],G9,tblDataBrut[Dispo],H9) -> 1
A10: 2026-08 | B10: 2026-S34 | C10: Tunis | D10: chaachoui youssef | E10: 46253 | F10: Octroi Classique | G10: CLA | H10: OUI | I10: =SUMIFS(tblDataBrut[Nombre de dossiers traités],tblDataBrut[Mois],A10,tblDataBrut[Semaine],B10,tblDataBrut[Site],C10,tblDataBrut[Collaborateur],D10,tblDataBrut[Date],E10,tblDataBrut[Activité],F10,tblDataBrut[Produit],G10,tblDataBrut[Dispo],H10) -> 1

Sheet Data brut
A1: DATA BRUT · TRAITEMENTS
A3: Données enrichies après fusion PersoID ↔ PERSOID · filtres Excel disponibles sur chaque colonne
A4: Le compteur vaut 1 par ligne de traitement. Les dossiers uniques sont calculés séparément dans le dashboard.
A6: Mois | B6: Semaine | C6: Date | D6: Site | E6: Collaborateur | F6: Activité | G6: Produit | H6: Dossier | I6: Décision | J6: Commentaire | K6: Dispo | L6: Nombre de dossiers traités | M6: PersoID | N6: Type dossier | O6: Date/heure
A7: 2026-08 | B7: 2026-S34 | C7: 46252 | D7: Tunis | E7: chaachoui youssef | F7: Octroi Classique | G7: CLA | H7: 123456 | I7: ACC VALIDE | J7: ok | K7: OUI | L7: 1 | M7: E16_G | N7: 1ère étude | O7: 46252.091
A8: 2026-08 | B8: 2026-S34 | C8: 46252 | D8: Tunis | E8: chaachoui youssef | F8: Live Console | G8: CCL SFR | H8: 123456 | I8: ACC VALIDE | J8: ok | K8: (Non renseigné) | L8: 1 | M8: E16_G | O8: 46252.091
A9: 2026-08 | B9: 2026-S34 | C9: 46252 | D9: Tunis | E9: chaachoui youssef | F9: Live Console | G9: CCL SFR | H9: 1234567 | I9: ACC VALIDE | J9: ok | K9: (Non renseigné) | L9: 1 | M9: E16_G | O9: 46252.092
A10: 2026-08 | B10: 2026-S34 | C10: 46252 | D10: Tunis | E10: chaachoui youssef | F10: Octroi Classique | G10: Lydia/BANKIN | H10: 123 | I10: ACC VALIDE | J10: ok | K10: OUI | L10: 1 | M10: E16_G | N10: 1ère étude | O10: 46252.472
A11: 2026-08 | B11: 2026-S34 | C11: 46252 | D11: Tunis | E11: chaachoui youssef | F11: Octroi Classique | G11: CLA | H11: 1 | I11: ACC VALIDE | J11: ok | K11: OUI | L11: 1 | M11: E16_G | N11: 1ère étude | O11: 46252.477
A12: 2026-08 | B12: 2026-S34 | C12: 46252 | D12: Tunis | E12: chaachoui youssef | F12: Octroi Classique | G12: CLA | H12: 12 | I12: ACC VALIDE | J12: ok | K12: OUI | L12: 1 | M12: E16_G | N12: 1ère étude | O12: 46252.477
A13: 2026-08 | B13: 2026-S34 | C13: 46253 | D13: Tunis | E13: chaachoui youssef | F13: Octroi Classique | G13: CLA | H13: 123456789 | I13: ACC VALIDE | J13: test | K13: OUI | L13: 1 | M13: E16_G | N13: 1ère étude | O13: 46253.686

Sheet Paramètres
A1: PARAMÈTRES DU DASHBOARD | H1: Mois | J1: Semaine | L1: Site | N1: Activité | P1: Produit | R1: Dispo | T1: Date
H2: Tous | J2: Tous | L2: Tous | N2: Tous | P2: Tous | R2: Tous | T2: Toutes
A3: Modifier uniquement les cellules bleu clair, puis utiliser Données > Actualiser tout après activation de Power Query | H3: {=_xlfn._xlws.SORT(_xlfn.UNIQUE(tblDataBrut[Mois]))} -> #NAME? | J3: {=_xlfn._xlws.SORT(_xlfn.UNIQUE(tblDataBrut[Semaine]))} -> #NAME? | L3: {=_xlfn._xlws.SORT(_xlfn.UNIQUE(tblDataBrut[Site]))} -> #NAME? | N3: {=_xlfn._xlws.SORT(_xlfn.UNIQUE(tblDataBrut[Activité]))} -> #NAME? | P3: {=_xlfn._xlws.SORT(_xlfn.UNIQUE(tblDataBrut[Produit]))} -> #NAME? | R3: {=_xlfn._xlws.SORT(_xlfn.UNIQUE(tblDataBrut[Dispo]))} -> #NAME? | T3: {=_xlfn._xlws.SORT(_xlfn.UNIQUE(tblDataBrut[Date]))} -> #NAME?
N4: #NAME? | P4: #NAME? | R4: #NAME? | T4: #NAME?
A5: Paramètre | B5: Valeur | C5: Utilisation | P5: #NAME?
A6: CheminSource | B6: C:\A_COMPLETER\Sources | C6: Dossier racine contenant année/mois, CSV agents et archive
A7: SeparateurCSV | B7: ; | C7: Séparateur utilisé par les fichiers CSV
A8: EncodageCSV | B8: 65001 | C8: 65001 = UTF-8
A9: CultureDate | B9: fr-FR | C9: Culture utilisée pour typer DateTime
A11: Listes de filtres dynamiques · alimentées par tblDataBrut

Sheet Annuaire
A1: ANNUAIRE DES AGENTS
A3: Référentiel utilisé pour la fusion : source[PersoID] = Annuaire[PERSOID]
A5: LOGID | B5: Site | C5: Nom | D5: Prénom | E5: PERSOID | F5: Nom Complet | G5: Email | H5: Code Sas | I5: Date embauche | J5: Manager | K5: Activité | L5: Sous activité
A6: 8858120 | B6: RABAT | C6: AAZAROU | D6: BOUTAYNA | E6: AAZAROBO | F6: AAZAROU BOUTAYNA | G6: planifetstat@e-i.com | H6: IPSAABO | I6: 46034 | J6: MOUNAJSO | K6: PRESSE | L6: La Presse
A7: 8858014 | B7: RABAT | C7: ABBASSI | D7: Yassir | E7: ABBASSYA | F7: ABBASSI Yassir | G7: planifetstat@e-i.com | H7: IPSABYA | I7: 45665 | J7: BELMALME | K7: COFIDIS | L7: COFIDIS DCL DRC DPA
A8: 123456 | B8: Tunis | C8: chaachoui | D8: youssef | E8: E16_G | F8: chaachoui youssef | G8: yc@yc.com | H8: ipchaach | I8: 43831 | J8: abcd | K8: data | L8: data

Sheet Guide Power Query
A1: GUIDE POWER QUERY
A3: Activation en 3 requêtes : qDataBrut, qStatistique et qStatAgent
A5: 1 | B5: Renseigner Paramètres!B6 avec le dossier racine. Folder.Files parcourt aussi les sous-dossiers année/mois et archive.
A6: 2 | B6: Excel > Données > Obtenir des données > À partir d'autres sources > Requête vide > Éditeur avancé.
A7: 3 | B7: Créer qDataBrut avec le code ci-dessous, puis charger dans Data brut et renommer la table tblDataBrut.
A8: 4 | B8: Créer qStatistique et qStatAgent en référence à qDataBrut, puis charger dans les feuilles correspondantes.
A9: 5 | B9: Utiliser Données > Actualiser tout. Contrôler la carte Agents non référencés : elle doit rester à zéro.
A11: Requête | B11: Code M à copier dans l'Éditeur avancé
A12: qDataBrut | B12: let
B13: Params = Excel.CurrentWorkbook(){[Name="tblParametres"]}[Content],
B14: Param = (Nom as text) as text => Text.From(Params{[Paramètre=Nom]}[Valeur]),
B15: Racine = Param("CheminSource"),
B16: Separateur = Param("SeparateurCSV"),
B17: Encodage = Number.FromText(Param("EncodageCSV")),
B18: Culture = Param("CultureDate"),
B19: Fichiers = Table.SelectRows(Folder.Files(Racine), each Text.Lower([Extension]) = ".csv" and not Text.StartsWith([Name], "~$")),
B20: AvecTables = Table.AddColumn(Fichiers, "Données", each Table.PromoteHeaders(Csv.Document([Content], [Delimiter=Separateur, Encoding=Encodage, QuoteStyle=QuoteStyle.Csv]), [PromoteAllScalars=true])),
B21: SourceCombinee = Table.Combine(AvecTables[Données]),
B22: NomsNettoyes = Table.TransformColumnNames(SourceCombinee, each Text.Trim(_)),
B23: Types = Table.TransformColumnTypes(NomsNettoyes, {{"NumeroDossier", type text}, {"PersoID", type text}, {"DateTime", type datetime}, {"Activite", type text}, {"Produit", type text}, {"TypeDossier", type text}, {"Decision", type text}, {"Dispo", type text}, {"Commentaire", type text}}, Culture),
B24: Annuaire0 = Excel.CurrentWorkbook(){[Name="tblAnnuaire"]}[Content],
... B38: Selection
A41: qStatistique | B41: let
B42: Source = qDataBrut,
B43: Resultat = Table.Group(Source, {"Mois", "Semaine", "Site", "Date", "Activité", "Produit", "Dispo"}, {{"Nombre de dossiers traités", each List.Sum([Nombre de dossiers traités]), Int64.Type}})
B44: in
B45: Resultat
A48: qStatAgent | B48: let
B49: Source = qDataBrut,
B50: Resultat = Table.Group(Source, {"Mois", "Semaine", "Site", "Collaborateur", "Date", "Activité", "Produit", "Dispo"}, {{"Nombre de dossiers traités", each List.Sum([Nombre de dossiers traités]), Int64.Type}})
B51: in
B52: Resultat
A55: Sources visuelles | B55: https://www.floabank.fr/ · https://www.brandcolorcode.com/floa-bank

Sheet source
A1: SOURCE · EXEMPLE
A3: Échantillon fourni dans le fichier d'origine · les CSV de production sont combinés par Power Query
A5: NumeroDossier | B5: PersoID | C5: DateTime | D5: Activite | E5: Produit | F5: TypeDossier | G5: Decision | H5: Dispo | I5: Commentaire
A6: 123456 | B6: E16_G | C6: 46252.091 | D6: Octroi Classique | E6: CLA | F6: 1ère étude | G6: ACC VALIDE | H6: OUI | I6: ok
A7: 123456 | B7: E16_G | C7: 46252.091 | D7: Live Console | E7: CCL SFR | G7: ACC VALIDE | I7: ok
A8: 1234567 | B8: E16_G | C8: 46252.092 | D8: Live Console | E8: CCL SFR | G8: ACC VALIDE | I8: ok
A9: 123 | B9: E16_G | C9: 46252.472 | D9: Octroi Classique | E9: Lydia/BANKIN | F9: 1ère étude | G9: ACC VALIDE | H9: OUI | I9: ok
A10: 1 | B10: E16_G | C10: 46252.477 | D10: Octroi Classique | E10: CLA | F10: 1ère étude | G10: ACC VALIDE | H10: OUI | I10: ok
A11: 12 | B11: E16_G | C11: 46252.477 | D11: Octroi Classique | E11: CLA | F11: 1ère étude | G11: ACC VALIDE | H11: OUI | I11: ok
A12: 123456789 | B12: E16_G | C12: 46253.686 | D12: Octroi Classique | E12: CLA | F12: 1ère étude | G12: ACC VALIDE | H12: OUI | I12: test
